Workbook

Sheet Tables
C1: Latency (seconds)
C3: Query | D3: MySQL | E3: MongoDB | H3: Query | I3: Metric | J3: MySQL | K3: MongoDB
C4: q1_top_cities | D4: =IFERROR(AVERAGEIFS(BenchmarkResults!$H:$H,BenchmarkResults!$C:$C,Tables!D$3,BenchmarkResults!$B:$B,Tables!$C4),"N/A") -> 676.7213 | E4: =IFERROR(AVERAGEIFS(BenchmarkResults!$H:$H,BenchmarkResults!$C:$C,Tables!E$3,BenchmarkResults!$B:$B,Tables!$C4),"N/A") -> N/A | H4: q1_top_cities | I4: Average CPU idle % | J4: {=_xlfn.XLOOKUP($I4,CalculatedMetrics!$A$25:$A$40,OFFSET(CalculatedMetrics!$A$25:$A$40,0,MATCH(1,(CalculatedMetrics!$A$1:$AK$1=Tables!J$3)*(CalculatedMetrics!$A$2:$AK$2=Tables!$H4),0)-1))} -> 62.834591 | K4: {=_xlfn.XLOOKUP($I4,CalculatedMetrics!$A$25:$A$40,OFFSET(CalculatedMetrics!$A$25:$A$40,0,MATCH(1,(CalculatedMetrics!$A$1:$AK$1=Tables!K$3)*(CalculatedMetrics!$A$2:$AK$2=Tables!$H4),0)-1))} -> 46.983287
C5: q2_avg_order_city | D5: =IFERROR(AVERAGEIFS(BenchmarkResults!$H:$H,BenchmarkResults!$C:$C,Tables!D$3,BenchmarkResults!$B:$B,Tables!$C5),"N/A") -> 383.16443 | E5: =IFERROR(AVERAGEIFS(BenchmarkResults!$H:$H,BenchmarkResults!$C:$C,Tables!E$3,BenchmarkResults!$B:$B,Tables!$C5),"N/A") -> 3289.542 | H5: =H4 -> q1_top_cities | I5: Δ swpd (KB) | J5: {=_xlfn.XLOOKUP($I5,CalculatedMetrics!$A$25:$A$40,OFFSET(CalculatedMetrics!$A$25:$A$40,0,MATCH(1,(CalculatedMetrics!$A$1:$AK$1=Tables!J$3)*(CalculatedMetrics!$A$2:$AK$2=Tables!$H5),0)-1))} -> 790993.33 | K5: {=_xlfn.XLOOKUP($I5,CalculatedMetrics!$A$25:$A$40,OFFSET(CalculatedMetrics!$A$25:$A$40,0,MATCH(1,(CalculatedMetrics!$A$1:$AK$1=Tables!K$3)*(CalculatedMetrics!$A$2:$AK$2=Tables!$H5),0)-1))} -> 80896
C6: q3_customer_spend_stats | D6: =IFERROR(AVERAGEIFS(BenchmarkResults!$H:$H,BenchmarkResults!$C:$C,Tables!D$3,BenchmarkResults!$B:$B,Tables!$C6),"N/A") -> 123.3866 | E6: =IFERROR(AVERAGEIFS(BenchmarkResults!$H:$H,BenchmarkResults!$C:$C,Tables!E$3,BenchmarkResults!$B:$B,Tables!$C6),"N/A") -> 226.09473 | H6: =H5 -> q1_top_cities | I6: Average swap in (KB/sec) | J6: {=_xlfn.XLOOKUP($I6,CalculatedMetrics!$A$25:$A$40,OFFSET(CalculatedMetrics!$A$25:$A$40,0,MATCH(1,(CalculatedMetrics!$A$1:$AK$1=Tables!J$3)*(CalculatedMetrics!$A$2:$AK$2=Tables!$H6),0)-1))} -> 16.09839 | K6: {=_xlfn.XLOOKUP($I6,CalculatedMetrics!$A$25:$A$40,OFFSET(CalculatedMetrics!$A$25:$A$40,0,MATCH(1,(CalculatedMetrics!$A$1:$AK$1=Tables!K$3)*(CalculatedMetrics!$A$2:$AK$2=Tables!$H6),0)-1))} -> 6.6044568
C7: q4_category_revenue | D7: =IFERROR(AVERAGEIFS(BenchmarkResults!$H:$H,BenchmarkResults!$C:$C,Tables!D$3,BenchmarkResults!$B:$B,Tables!$C7),"N/A") -> 197.9257 | E7: =IFERROR(AVERAGEIFS(BenchmarkResults!$H:$H,BenchmarkResults!$C:$C,Tables!E$3,BenchmarkResults!$B:$B,Tables!$C7),"N/A") -> 2491.3991 | H7: =H6 -> q1_top_cities | I7: Average swap out (KB/sec) | J7: {=_xlfn.XLOOKUP($I7,CalculatedMetrics!$A$25:$A$40,OFFSET(CalculatedMetrics!$A$25:$A$40,0,MATCH(1,(CalculatedMetrics!$A$1:$AK$1=Tables!J$3)*(CalculatedMetrics!$A$2:$AK$2=Tables!$H7),0)-1))} -> 29 | K7: {=_xlfn.XLOOKUP($I7,CalculatedMetrics!$A$25:$A$40,OFFSET(CalculatedMetrics!$A$25:$A$40,0,MATCH(1,(CalculatedMetrics!$A$1:$AK$1=Tables!K$3)*(CalculatedMetrics!$A$2:$AK$2=Tables!$H7),0)-1))} -> 5527
C8: q5_top_customers | D8: =IFERROR(AVERAGEIFS(BenchmarkResults!$H:$H,BenchmarkResults!$C:$C,Tables!D$3,BenchmarkResults!$B:$B,Tables!$C8),"N/A") -> 553.5006 | E8: =IFERROR(AVERAGEIFS(BenchmarkResults!$H:$H,BenchmarkResults!$C:$C,Tables!E$3,BenchmarkResults!$B:$B,Tables!$C8),"N/A") -> 176.9879 | H8: q2_avg_order_city | I8: Average CPU idle % | J8: {=_xlfn.XLOOKUP($I8,CalculatedMetrics!$A$25:$A$40,OFFSET(CalculatedMetrics!$A$25:$A$40,0,MATCH(1,(CalculatedMetrics!$A$1:$AK$1=Tables!J$3)*(CalculatedMetrics!$A$2:$AK$2=Tables!$H8),0)-1))} -> 62.333564 | K8: {=_xlfn.XLOOKUP($I8,CalculatedMetrics!$A$25:$A$40,OFFSET(CalculatedMetrics!$A$25:$A$40,0,MATCH(1,(CalculatedMetrics!$A$1:$AK$1=Tables!K$3)*(CalculatedMetrics!$A$2:$AK$2=Tables!$H8),0)-1))} -> 64.467526
C9: q6_inactive_customers | D9: =IFERROR(AVERAGEIFS(BenchmarkResults!$H:$H,BenchmarkResults!$C:$C,Tables!D$3,BenchmarkResults!$B:$B,Tables!$C9),"N/A") -> 466.39043 | E9: =IFERROR(AVERAGEIFS(BenchmarkResults!$H:$H,BenchmarkResults!$C:$C,Tables!E$3,BenchmarkResults!$B:$B,Tables!$C9),"N/A") -> 2554.9402 | H9: =H8 -> q2_avg_order_city | I9: Δ swpd (KB) | J9: {=_xlfn.XLOOKUP($I9,CalculatedMetrics!$A$25:$A$40,OFFSET(CalculatedMetrics!$A$25:$A$40,0,MATCH(1,(CalculatedMetrics!$A$1:$AK$1=Tables!J$3)*(CalculatedMetrics!$A$2:$AK$2=Tables!$H9),0)-1))} -> -226286.67 | K9: {=_xlfn.XLOOKUP($I9,CalculatedMetrics!$A$25:$A$40,OFFSET(CalculatedMetrics!$A$25:$A$40,0,MATCH(1,(CalculatedMetrics!$A$1:$AK$1=Tables!K$3)*(CalculatedMetrics!$A$2:$AK$2=Tables!$H9),0)-1))} -> -682.66667
H10: =H9 -> q2_avg_order_city | I10: Average swap in (KB/sec) | J10: {=_xlfn.XLOOKUP($I10,CalculatedMetrics!$A$25:$A$40,OFFSET(CalculatedMetrics!$A$25:$A$40,0,MATCH(1,(CalculatedMetrics!$A$1:$AK$1=Tables!J$3)*(CalculatedMetrics!$A$2:$AK$2=Tables!$H10),0)-1))} -> 7.4920305 | K10: {=_xlfn.XLOOKUP($I10,CalculatedMetrics!$A$25:$A$40,OFFSET(CalculatedMetrics!$A$25:$A$40,0,MATCH(1,(CalculatedMetrics!$A$1:$AK$1=Tables!K$3)*(CalculatedMetrics!$A$2:$AK$2=Tables!$H10),0)-1))} -> 0.45254606
C11: CPU usage | H11: =H10 -> q2_avg_order_city | I11: Average swap out (KB/sec) | J11: {=_xlfn.XLOOKUP($I11,CalculatedMetrics!$A$25:$A$40,OFFSET(CalculatedMetrics!$A$25:$A$40,0,MATCH(1,(CalculatedMetrics!$A$1:$AK$1=Tables!J$3)*(CalculatedMetrics!$A$2:$AK$2=Tables!$H11),0)-1))} -> 0 | K11: {=_xlfn.XLOOKUP($I11,CalculatedMetrics!$A$25:$A$40,OFFSET(CalculatedMetrics!$A$25:$A$40,0,MATCH(1,(CalculatedMetrics!$A$1:$AK$1=Tables!K$3)*(CalculatedMetrics!$A$2:$AK$2=Tables!$H11),0)-1))} -> 10.333333
H12: q3_customer_spend_stats | I12: Average CPU idle % | J12: {=_xlfn.XLOOKUP($I12,CalculatedMetrics!$A$25:$A$40,OFFSET(CalculatedMetrics!$A$25:$A$40,0,MATCH(1,(CalculatedMetrics!$A$1:$AK$1=Tables!J$3)*(CalculatedMetrics!$A$2:$AK$2=Tables!$H12),0)-1))} -> 81.553535 | K12: {=_xlfn.XLOOKUP($I12,CalculatedMetrics!$A$25:$A$40,OFFSET(CalculatedMetrics!$A$25:$A$40,0,MATCH(1,(CalculatedMetrics!$A$1:$AK$1=Tables!K$3)*(CalculatedMetrics!$A$2:$AK$2=Tables!$H12),0)-1))} -> 62.314394
B13: Query | C13: Metric | D13: MySQL | E13: MongoDB | H13: =H12 -> q3_customer_spend_stats | I13: Δ swpd (KB) | J13: {=_xlfn.XLOOKUP($I13,CalculatedMetrics!$A$25:$A$40,OFFSET(CalculatedMetrics!$A$25:$A$40,0,MATCH(1,(CalculatedMetrics!$A$1:$AK$1=Tables!J$3)*(CalculatedMetrics!$A$2:$AK$2=Tables!$H13),0)-1))} -> 70625.333 | K13: {=_xlfn.XLOOKUP($I13,CalculatedMetrics!$A$25:$A$40,OFFSET(CalculatedMetrics!$A$25:$A$40,0,MATCH(1,(CalculatedMetrics!$A$1:$AK$1=Tables!K$3)*(CalculatedMetrics!$A$2:$AK$2=Tables!$H13),0)-1))} -> -1621.3333
B14: q1_top_cities | C14: Avg. CPU usage % | D14: =IFERROR(AVERAGEIFS(mysql_hardware_log!$O$3:$O$722,mysql_hardware_log!$A$3:$A$722,B14),"N/A") -> 32.267327 | E14: =IFERROR(AVERAGEIFS(mongodb_hardware_log!$O$3:$O$3476,mongodb_hardware_log!$A$3:$A$3476,B14),"N/A") -> 20.320334 | H14: =H13 -> q3_customer_spend_stats | I14: Average swap in (KB/sec) | J14: {=_xlfn.XLOOKUP($I14,CalculatedMetrics!$A$25:$A$40,OFFSET(CalculatedMetrics!$A$25:$A$40,0,MATCH(1,(CalculatedMetrics!$A$1:$AK$1=Tables!J$3)*(CalculatedMetrics!$A$2:$AK$2=Tables!$H14),0)-1))} -> 0.17171717 | K14: {=_xlfn.XLOOKUP($I14,CalculatedMetrics!$A$25:$A$40,OFFSET(CalculatedMetrics!$A$25:$A$40,0,MATCH(1,(CalculatedMetrics!$A$1:$AK$1=Tables!K$3)*(CalculatedMetrics!$A$2:$AK$2=Tables!$H14),0)-1))} -> 20.877525
C15: Avg. CPU wait % | D15: =IFERROR(AVERAGEIFS(mysql_hardware_log!$R$3:$R$722,mysql_hardware_log!$A$3:$A$722,B14),"N/A") -> 1.2722772 | E15: =IFERROR(AVERAGEIFS(mongodb_hardware_log!$R$3:$R$3476,mongodb_hardware_log!$A$3:$A$3476,B14),"N/A") -> 24.827298 | H15: =H14 -> q3_customer_spend_stats | I15: Average swap out (KB/sec) | J15: {=_xlfn.XLOOKUP($I15,CalculatedMetrics!$A$25:$A$40,OFFSET(CalculatedMetrics!$A$25:$A$40,0,MATCH(1,(CalculatedMetrics!$A$1:$AK$1=Tables!J$3)*(CalculatedMetrics!$A$2:$AK$2=Tables!$H15),0)-1))} -> 0 | K15: {=_xlfn.XLOOKUP($I15,CalculatedMetrics!$A$25:$A$40,OFFSET(CalculatedMetrics!$A$25:$A$40,0,MATCH(1,(CalculatedMetrics!$A$1:$AK$1=Tables!K$3)*(CalculatedMetrics!$A$2:$AK$2=Tables!$H15),0)-1))} -> 310
B16: q2_avg_order_city | C16: Avg. CPU usage % | D16: =IFERROR(AVERAGEIFS(mysql_hardware_log!$O$3:$O$722,mysql_hardware_log!$A$3:$A$722,B16),"N/A") -> 30.095652 | E16: =IFERROR(AVERAGEIFS(mongodb_hardware_log!$O$3:$O$3476,mongodb_hardware_log!$A$3:$A$3476,B16),"N/A") -> 33.256332 | H16: q4_category_revenue | I16: Average CPU idle % | J16: {=_xlfn.XLOOKUP($I16,CalculatedMetrics!$A$25:$A$40,OFFSET(CalculatedMetrics!$A$25:$A$40,0,MATCH(1,(CalculatedMetrics!$A$1:$AK$1=Tables!J$3)*(CalculatedMetrics!$A$2:$AK$2=Tables!$H16),0)-1))} -> 60.944444 | K16: {=_xlfn.XLOOKUP($I16,CalculatedMetrics!$A$25:$A$40,OFFSET(CalculatedMetrics!$A$25:$A$40,0,MATCH(1,(CalculatedMetrics!$A$1:$AK$1=Tables!K$3)*(CalculatedMetrics!$A$2:$AK$2=Tables!$H16),0)-1))} -> 47.505369
C17: Avg. CPU wait % | D17: =IFERROR(AVERAGEIFS(mysql_hardware_log!$R$3:$R$722,mysql_hardware_log!$A$3:$A$722,B16),"N/A") -> 3.5304348 | E17: =IFERROR(AVERAGEIFS(mongodb_hardware_log!$R$3:$R$3476,mongodb_hardware_log!$A$3:$A$3476,B16),"N/A") -> 0.28368794 | H17: =H16 -> q4_category_revenue | I17: Δ swpd (KB) | J17: {=_xlfn.XLOOKUP($I17,CalculatedMetrics!$A$25:$A$40,OFFSET(CalculatedMetrics!$A$25:$A$40,0,MATCH(1,(CalculatedMetrics!$A$1:$AK$1=Tables!J$3)*(CalculatedMetrics!$A$2:$AK$2=Tables!$H17),0)-1))} -> -110541.33 | K17: {=_xlfn.XLOOKUP($I17,CalculatedMetrics!$A$25:$A$40,OFFSET(CalculatedMetrics!$A$25:$A$40,0,MATCH(1,(CalculatedMetrics!$A$1:$AK$1=Tables!K$3)*(CalculatedMetrics!$A$2:$AK$2=Tables!$H17),0)-1))} -> 25770.667
B18: q3_customer_spend_stats | C18: Avg. CPU usage % | D18: =IFERROR(AVERAGEIFS(mysql_hardware_log!$O$3:$O$722,mysql_hardware_log!$A$3:$A$722,B18),"N/A") -> 11.891892 | E18: =IFERROR(AVERAGEIFS(mongodb_hardware_log!$O$3:$O$3476,mongodb_hardware_log!$A$3:$A$3476,B18),"N/A") -> 30.617647 | H18: =H17 -> q4_category_revenue | I18: Average swap in (KB/sec) | J18: {=_xlfn.XLOOKUP($I18,CalculatedMetrics!$A$25:$A$40,OFFSET(CalculatedMetrics!$A$25:$A$40,0,MATCH(1,(CalculatedMetrics!$A$1:$AK$1=Tables!J$3)*(CalculatedMetrics!$A$2:$AK$2=Tables!$H18),0)-1))} -> 30.958333 | K18: {=_xlfn.XLOOKUP($I18,CalculatedMetrics!$A$25:$A$40,OFFSET(CalculatedMetrics!$A$25:$A$40,0,MATCH(1,(CalculatedMetrics!$A$1:$AK$1=Tables!K$3)*(CalculatedMetrics!$A$2:$AK$2=Tables!$H18),0)-1))} -> 15.018425
C19: Avg. CPU wait % | D19: =IFERROR(AVERAGEIFS(mysql_hardware_log!$R$3:$R$722,mysql_hardware_log!$A$3:$A$722,B18),"N/A") -> 4.3243243 | E19: =IFERROR(AVERAGEIFS(mongodb_hardware_log!$R$3:$R$3476,mongodb_hardware_log!$A$3:$A$3476,B18),"N/A") -> 3.7352941 | H19: =H18 -> q4_category_revenue | I19: Average swap out (KB/sec) | J19: {=_xlfn.XLOOKUP($I19,CalculatedMetrics!$A$25:$A$40,OFFSET(CalculatedMetrics!$A$25:$A$40,0,MATCH(1,(CalculatedMetrics!$A$1:$AK$1=Tables!J$3)*(CalculatedMetrics!$A$2:$AK$2=Tables!$H19),0)-1))} -> 0 | K19: {=_xlfn.XLOOKUP($I19,CalculatedMetrics!$A$25:$A$40,OFFSET(CalculatedMetrics!$A$25:$A$40,0,MATCH(1,(CalculatedMetrics!$A$1:$AK$1=Tables!K$3)*(CalculatedMetrics!$A$2:$AK$2=Tables!$H19),0)-1))} -> 2103.6667
B20: q4_category_revenue | C20: Avg. CPU usage % | D20: =IFERROR(AVERAGEIFS(mysql_hardware_log!$O$3:$O$722,mysql_hardware_log!$A$3:$A$722,B20),"N/A") -> 36.216667 | E20: =IFERROR(AVERAGEIFS(mongodb_hardware_log!$O$3:$O$3476,mongodb_hardware_log!$A$3:$A$3476,B20),"N/A") -> 19.481928 | H20: q5_top_customers | I20: Average CPU idle % | J20: {=_xlfn.XLOOKUP($I20,CalculatedMetrics!$A$25:$A$40,OFFSET(CalculatedMetrics!$A$25:$A$40,0,MATCH(1,(CalculatedMetrics!$A$1:$AK$1=Tables!J$3)*(CalculatedMetrics!$A$2:$AK$2=Tables!$H20),0)-1))} -> 56.090999 | K20: {=_xlfn.XLOOKUP($I20,CalculatedMetrics!$A$25:$A$40,OFFSET(CalculatedMetrics!$A$25:$A$40,0,MATCH(1,(CalculatedMetrics!$A$1:$AK$1=Tables!K$3)*(CalculatedMetrics!$A$2:$AK$2=Tables!$H20),0)-1))} -> 60.485839
C21: Avg. CPU wait % | D21: =IFERROR(AVERAGEIFS(mysql_hardware_log!$R$3:$R$722,mysql_hardware_log!$A$3:$A$722,B20),"N/A") -> 0.05 | E21: =IFERROR(AVERAGEIFS(mongodb_hardware_log!$R$3:$R$3476,mongodb_hardware_log!$A$3:$A$3476,B20),"N/A") -> 24.635877 | H21: =H20 -> q5_top_customers | I21: Δ swpd (KB) | J21: {=_xlfn.XLOOKUP($I21,CalculatedMetrics!$A$25:$A$40,OFFSET(CalculatedMetrics!$A$25:$A$40,0,MATCH(1,(CalculatedMetrics!$A$1:$AK$1=Tables!J$3)*(CalculatedMetrics!$A$2:$AK$2=Tables!$H21),0)-1))} -> 189834.67 | K21: {=_xlfn.XLOOKUP($I21,CalculatedMetrics!$A$25:$A$40,OFFSET(CalculatedMetrics!$A$25:$A$40,0,MATCH(1,(CalculatedMetrics!$A$1:$AK$1=Tables!K$3)*(CalculatedMetrics!$A$2:$AK$2=Tables!$H21),0)-1))} -> 0
B22: q5_top_customers | C22: Avg. CPU usage % | D22: =IFERROR(AVERAGEIFS(mysql_hardware_log!$O$3:$O$722,mysql_hardware_log!$A$3:$A$722,B22),"N/A") -> 36.10241 | E22: =IFERROR(AVERAGEIFS(mongodb_hardware_log!$O$3:$O$3476,mongodb_hardware_log!$A$3:$A$3476,B22),"N/A") -> 30 | H22: =H21 -> q5_top_customers | I22: Average swap in (KB/sec) | J22: {=_xlfn.XLOOKUP($I22,CalculatedMetrics!$A$25:$A$40,OFFSET(CalculatedMetrics!$A$25:$A$40,0,MATCH(1,(CalculatedMetrics!$A$1:$AK$1=Tables!J$3)*(CalculatedMetrics!$A$2:$AK$2=Tables!$H22),0)-1))} -> 15.729148 | K22: {=_xlfn.XLOOKUP($I22,CalculatedMetrics!$A$25:$A$40,OFFSET(CalculatedMetrics!$A$25:$A$40,0,MATCH(1,(CalculatedMetrics!$A$1:$AK$1=Tables!K$3)*(CalculatedMetrics!$A$2:$AK$2=Tables!$H22),0)-1))} -> 35.27451
C23: Avg. CPU wait % | D23: =IFERROR(AVERAGEIFS(mysql_hardware_log!$R$3:$R$722,mysql_hardware_log!$A$3:$A$722,B22),"N/A") -> 2.8373494 | E23: =IFERROR(AVERAGEIFS(mongodb_hardware_log!$R$3:$R$3476,mongodb_hardware_log!$A$3:$A$3476,B22),"N/A") -> 6.2264151 | H23: =H22 -> q5_top_customers | I23: Average swap out (KB/sec) | J23: {=_xlfn.XLOOKUP($I23,CalculatedMetrics!$A$25:$A$40,OFFSET(CalculatedMetrics!$A$25:$A$40,0,MATCH(1,(CalculatedMetrics!$A$1:$AK$1=Tables!J$3)*(CalculatedMetrics!$A$2:$AK$2=Tables!$H23),0)-1))} -> 37 | K23: {=_xlfn.XLOOKUP($I23,CalculatedMetrics!$A$25:$A$40,OFFSET(CalculatedMetrics!$A$25:$A$40,0,MATCH(1,(CalculatedMetrics!$A$1:$AK$1=Tables!K$3)*(CalculatedMetrics!$A$2:$AK$2=Tables!$H23),0)-1))} -> 460.33333
B24: q6_inactive_customers | C24: Avg. CPU usage % | D24: =IFERROR(AVERAGEIFS(mysql_hardware_log!$O$3:$O$722,mysql_hardware_log!$A$3:$A$722,B24),"N/A") -> 22.735714 | E24: =IFERROR(AVERAGEIFS(mongodb_hardware_log!$O$3:$O$3476,mongodb_hardware_log!$A$3:$A$3476,B24),"N/A") -> 33.839683 | H24: q6_inactive_customers | I24: Average CPU idle % | J24: {=_xlfn.XLOOKUP($I24,CalculatedMetrics!$A$25:$A$40,OFFSET(CalculatedMetrics!$A$25:$A$40,0,MATCH(1,(CalculatedMetrics!$A$1:$AK$1=Tables!J$3)*(CalculatedMetrics!$A$2:$AK$2=Tables!$H24),0)-1))} -> 61.851449 | K24: {=_xlfn.XLOOKUP($I24,CalculatedMetrics!$A$25:$A$40,OFFSET(CalculatedMetrics!$A$25:$A$40,0,MATCH(1,(CalculatedMetrics!$A$1:$AK$1=Tables!K$3)*(CalculatedMetrics!$A$2:$AK$2=Tables!$H24),0)-1))} -> 63.498676
C25: Avg. CPU wait % | D25: =IFERROR(AVERAGEIFS(mysql_hardware_log!$R$3:$R$722,mysql_hardware_log!$A$3:$A$722,B24),"N/A") -> 3.4714286 | E25: =IFERROR(AVERAGEIFS(mongodb_hardware_log!$R$3:$R$3476,mongodb_hardware_log!$A$3:$A$3476,B24),"N/A") -> 0.67857143 | H25: =H24 -> q6_inactive_customers | I25: Δ swpd (KB) | J25: {=_xlfn.XLOOKUP($I25,CalculatedMetrics!$A$25:$A$40,OFFSET(CalculatedMetrics!$A$25:$A$40,0,MATCH(1,(CalculatedMetrics!$A$1:$AK$1=Tables!J$3)*(CalculatedMetrics!$A$2:$AK$2=Tables!$H25),0)-1))} -> -187777.33 | K25: {=_xlfn.XLOOKUP($I25,CalculatedMetrics!$A$25:$A$40,OFFSET(CalculatedMetrics!$A$25:$A$40,0,MATCH(1,(CalculatedMetrics!$A$1:$AK$1=Tables!K$3)*(CalculatedMetrics!$A$2:$AK$2=Tables!$H25),0)-1))} -> -7850.6667
H26: =H25 -> q6_inactive_customers | I26: Average swap in (KB/sec) | J26: {=_xlfn.XLOOKUP($I26,CalculatedMetrics!$A$25:$A$40,OFFSET(CalculatedMetrics!$A$25:$A$40,0,MATCH(1,(CalculatedMetrics!$A$1:$AK$1=Tables!J$3)*(CalculatedMetrics!$A$2:$AK$2=Tables!$H26),0)-1))} -> 0.15791063 | K26: {=_xlfn.XLOOKUP($I26,CalculatedMetrics!$A$25:$A$40,OFFSET(CalculatedMetrics!$A$25:$A$40,0,MATCH(1,(CalculatedMetrics!$A$1:$AK$1=Tables!K$3)*(CalculatedMetrics!$A$2:$AK$2=Tables!$H26),0)-1))} -> 3.2302342
C27: Memory usage | H27: =H26 -> q6_inactive_customers | I27: Average swap out (KB/sec) | J27: {=_xlfn.XLOOKUP($I27,CalculatedMetrics!$A$25:$A$40,OFFSET(CalculatedMetrics!$A$25:$A$40,0,MATCH(1,(CalculatedMetrics!$A$1:$AK$1=Tables!J$3)*(CalculatedMetrics!$A$2:$AK$2=Tables!$H27),0)-1))} -> 236 | K27: {=_xlfn.XLOOKUP($I27,CalculatedMetrics!$A$25:$A$40,OFFSET(CalculatedMetrics!$A$25:$A$40,0,MATCH(1,(CalculatedMetrics!$A$1:$AK$1=Tables!K$3)*(CalculatedMetrics!$A$2:$AK$2=Tables!$H27),0)-1))} -> 0
B29: Query | C29: Metric | D29: MySQL | E29: MongoDB
B30: q1_top_cities | C30: Avg. free mem. (MB) | D30: =AVERAGEIFS(mysql_hardware_log!$F$3:$F$722,mysql_hardware_log!$A$3:$A$722,B30)/1024 -> 335.94589 | E30: =AVERAGEIFS(mongodb_hardware_log!$F$3:$F$3476,mongodb_hardware_log!$A$3:$A$3476,B30)/1024 -> 149.01238
C31: Min. free mem. (MB) | D31: =_xlfn.MINIFS(mysql_hardware_log!$F$3:$F$722,mysql_hardware_log!$A$3:$A$722,B30)/1024 -> 95.199219 | E31: =_xlfn.MINIFS(mongodb_hardware_log!$F$3:$F$3476,mongodb_hardware_log!$A$3:$A$3476,B30)/1024 -> 97.078125
B32: q2_avg_order_city | C32: Avg. free mem. (MB) | D32: =AVERAGEIFS(mysql_hardware_log!$F$3:$F$722,mysql_hardware_log!$A$3:$A$722,B32)/1024 -> 199.13427 | E32: =AVERAGEIFS(mongodb_hardware_log!$F$3:$F$3476,mongodb_hardware_log!$A$3:$A$3476,B32)/1024 -> 489.29236
C33: Min. free mem. (MB) | D33: =_xlfn.MINIFS(mysql_hardware_log!$F$3:$F$722,mysql_hardware_log!$A$3:$A$722,B32)/1024 -> 101.78906 | E33: =_xlfn.MINIFS(mongodb_hardware_log!$F$3:$F$3476,mongodb_hardware_log!$A$3:$A$3476,B32)/1024 -> 97.617188
B34: q3_customer_spend_stats | C34: Avg. free mem. (MB) | D34: =AVERAGEIFS(mysql_hardware_log!$F$3:$F$722,mysql_hardware_log!$A$3:$A$722,B34)/1024 -> 556.35674 | E34: =AVERAGEIFS(mongodb_hardware_log!$F$3:$F$3476,mongodb_hardware_log!$A$3:$A$3476,B34)/1024 -> 180.68825
C35: Min. free mem. (MB) | D35: =_xlfn.MINIFS(mysql_hardware_log!$F$3:$F$722,mysql_hardware_log!$A$3:$A$722,B34)/1024 -> 104.07031 | E35: =_xlfn.MINIFS(mongodb_hardware_log!$F$3:$F$3476,mongodb_hardware_log!$A$3:$A$3476,B34)/1024 -> 100.66406
B36: q4_category_revenue | C36: Avg. free mem. (MB) | D36: =AVERAGEIFS(mysql_hardware_log!$F$3:$F$722,mysql_hardware_log!$A$3:$A$722,B36)/1024 -> 1084.8531 | E36: =AVERAGEIFS(mongodb_hardware_log!$F$3:$F$3476,mongodb_hardware_log!$A$3:$A$3476,B36)/1024 -> 143.157
C37: Min. free mem. (MB) | D37: =_xlfn.MINIFS(mysql_hardware_log!$F$3:$F$722,mysql_hardware_log!$A$3:$A$722,B36)/1024 -> 176.44531 | E37: =_xlfn.MINIFS(mongodb_hardware_log!$F$3:$F$3476,mongodb_hardware_log!$A$3:$A$3476,B36)/1024 -> 96.058594
B38: q5_top_customers | C38: Avg. free mem. (MB) | D38: =AVERAGEIFS(mysql_hardware_log!$F$3:$F$722,mysql_hardware_log!$A$3:$A$722,B38)/1024 -> 532.32354 | E38: =AVERAGEIFS(mongodb_hardware_log!$F$3:$F$3476,mongodb_hardware_log!$A$3:$A$3476,B38)/1024 -> 149.46123
C39: Min. free mem. (MB) | D39: =_xlfn.MINIFS(mysql_hardware_log!$F$3:$F$722,mysql_hardware_log!$A$3:$A$722,B38)/1024 -> 97.003906 | E39: =_xlfn.MINIFS(mongodb_hardware_log!$F$3:$F$3476,mongodb_hardware_log!$A$3:$A$3476,B38)/1024 -> 102.67969
B40: q6_inactive_customers | C40: Avg. free mem. (MB) | D40: =AVERAGEIFS(mysql_hardware_log!$F$3:$F$722,mysql_hardware_log!$A$3:$A$722,B40)/1024 -> 1076.7036 | E40: =AVERAGEIFS(mongodb_hardware_log!$F$3:$F$3476,mongodb_hardware_log!$A$3:$A$3476,B40)/1024 -> 311.1291
C41: Min. free mem. (MB) | D41: =_xlfn.MINIFS(mysql_hardware_log!$F$3:$F$722,mysql_hardware_log!$A$3:$A$722,B40)/1024 -> 104.85547 | E41: =_xlfn.MINIFS(mongodb_hardware_log!$F$3:$F$3476,mongodb_hardware_log!$A$3:$A$3476,B40)/1024 -> 101.92578

Sheet CalculatedMetrics
A1: System | B1: MongoDB | E1: MongoDB | H1: MongoDB | K1: MongoDB | N1: MongoDB | Q1: MongoDB | T1: MySQL | W1: MySQL | Z1: MySQL | AC1: MySQL | AF1: MySQL | AI1: MySQL
A2: Query | B2: q1_top_cities | E2: q2_avg_order_city | H2: q3_customer_spend_stats | K2: q4_category_revenue | N2: q5_top_customers | Q2: q6_inactive_customers | T2: q1_top_cities | W2: q2_avg_order_city | Z2: q3_customer_spend_stats | AC2: q4_category_revenue | AF2: q5_top_customers | AI2: q6_inactive_customers
A3: Iteration | B3: 1 | C3: 2 | D3: 3 | E3: 1 | F3: 2 | G3: 3 | H3: 1 | I3: 2 | J3: 3 | K3: 1 | L3: 2 | M3: 3 | N3: 1 | O3: 2 | P3: 3 | Q3: 1 | R3: 2 | S3: 3 | T3: 1 | U3: 2 | V3: 3 | W3: 1 | X3: 2 | Y3: 3 | Z3: 1 | AA3: 2 | AB3: 3 | AC3: 1 | AD3: 2 | AE3: 3 | AF3: 1 | AG3: 2 | AH3: 3 | AI3: 1 | AJ3: 2 | AK3: 3
A4: Latency (secs) | B4: N/A | C4: DNR | D4: DNR | E4: {=INDEX(BenchmarkResults!$B$2:$L$35,MATCH(1,(BenchmarkResults!$C$2:$C$35=CalculatedMetrics!E$1)*(BenchmarkResults!$B$2:$B$35=CalculatedMetrics!E$2)*(BenchmarkResults!$D$2:$D$35=CalculatedMetrics!E$3),0),7)} -> 3314.6677 | F4: {=INDEX(BenchmarkResults!$B$2:$L$35,MATCH(1,(BenchmarkResults!$C$2:$C$35=CalculatedMetrics!E$1)*(BenchmarkResults!$B$2:$B$35=CalculatedMetrics!E$2)*(BenchmarkResults!$D$2:$D$35=CalculatedMetrics!F$3),0),7)} -> 3337.8917 | G4: {=INDEX(BenchmarkResults!$B$2:$L$35,MATCH(1,(BenchmarkResults!$C$2:$C$35=CalculatedMetrics!E$1)*(BenchmarkResults!$B$2:$B$35=CalculatedMetrics!E$2)*(BenchmarkResults!$D$2:$D$35=CalculatedMetrics!G$3),0),7)} -> 3216.0666 | H4: {=INDEX(BenchmarkResults!$B$2:$L$35,MATCH(1,(BenchmarkResults!$C$2:$C$35=CalculatedMetrics!H$1)*(BenchmarkResults!$B$2:$B$35=CalculatedMetrics!H$2)*(BenchmarkResults!$D$2:$D$35=CalculatedMetrics!H$3),0),7)} -> 236.3744 | I4: {=INDEX(BenchmarkResults!$B$2:$L$35,MATCH(1,(BenchmarkResults!$C$2:$C$35=CalculatedMetrics!H$1)*(BenchmarkResults!$B$2:$B$35=CalculatedMetrics!H$2)*(BenchmarkResults!$D$2:$D$35=CalculatedMetrics!I$3),0),7)} -> 222.6706 | J4: {=INDEX(BenchmarkResults!$B$2:$L$35,MATCH(1,(BenchmarkResults!$C$2:$C$35=CalculatedMetrics!H$1)*(BenchmarkResults!$B$2:$B$35=CalculatedMetrics!H$2)*(BenchmarkResults!$D$2:$D$35=CalculatedMetrics!J$3),0),7)} -> 219.2392 | K4: {=INDEX(BenchmarkResults!$B$2:$L$35,MATCH(1,(BenchmarkResults!$C$2:$C$35=CalculatedMetrics!K$1)*(BenchmarkResults!$B$2:$B$35=CalculatedMetrics!K$2)*(BenchmarkResults!$D$2:$D$35=CalculatedMetrics!K$3),0),7)} -> 2439.8207 | L4: {=INDEX(BenchmarkResults!$B$2:$L$35,MATCH(1,(BenchmarkResults!$C$2:$C$35=CalculatedMetrics!K$1)*(BenchmarkResults!$B$2:$B$35=CalculatedMetrics!K$2)*(BenchmarkResults!$D$2:$D$35=CalculatedMetrics!L$3),0),7)} -> 2498.857 | M4: {=INDEX(BenchmarkResults!$B$2:$L$35,MATCH(1,(BenchmarkResults!$C$2:$C$35=CalculatedMetrics!K$1)*(BenchmarkResults!$B$2:$B$35=CalculatedMetrics!K$2)*(BenchmarkResults!$D$2:$D$35=CalculatedMetrics!M$3),0),7)} -> 2535.5197 | N4: {=INDEX(BenchmarkResults!$B$2:$L$35,MATCH(1,(BenchmarkResults!$C$2:$C$35=CalculatedMetrics!N$1)*(BenchmarkResults!$B$2:$B$35=CalculatedMetrics!N$2)*(BenchmarkResults!$D$2:$D$35=CalculatedMetrics!N$3),0),7)} -> 176.5896 | O4: {=INDEX(BenchmarkResults!$B$2:$L$35,MATCH(1,(BenchmarkResults!$C$2:$C$35=CalculatedMetrics!N$1)*(BenchmarkResults!$B$2:$B$35=CalculatedMetrics!N$2)*(BenchmarkResults!$D$2:$D$35=CalculatedMetrics!O$3),0),7)} -> 171.4585 | P4: {=INDEX(BenchmarkResults!$B$2:$L$35,MATCH(1,(BenchmarkResults!$C$2:$C$35=CalculatedMetrics!N$1)*(BenchmarkResults!$B$2:$B$35=CalculatedMetrics!N$2)*(BenchmarkResults!$D$2:$D$35=CalculatedMetrics!P$3),0),7)} -> 182.9156 | Q4: {=INDEX(BenchmarkResults!$B$2:$L$35,MATCH(1,(BenchmarkResults!$C$2:$C$35=CalculatedMetrics!Q$1)*(BenchmarkResults!$B$2:$B$35=CalculatedMetrics!Q$2)*(BenchmarkResults!$D$2:$D$35=CalculatedMetrics!Q$3),0),7)} -> 2693.8289 | R4: {=INDEX(BenchmarkResults!$B$2:$L$35,MATCH(1,(BenchmarkResults!$C$2:$C$35=CalculatedMetrics!Q$1)*(BenchmarkResults!$B$2:$B$35=CalculatedMetrics!Q$2)*(BenchmarkResults!$D$2:$D$35=CalculatedMetrics!R$3),0),7)} -> 2477.4293 | S4: {=INDEX(BenchmarkResults!$B$2:$L$35,MATCH(1,(BenchmarkResults!$C$2:$C$35=CalculatedMetrics!Q$1)*(BenchmarkResults!$B$2:$B$35=CalculatedMetrics!Q$2)*(BenchmarkResults!$D$2:$D$35=CalculatedMetrics!S$3),0),7)} -> 2493.5625 | T4: {=INDEX(BenchmarkResults!$B$2:$L$35,MATCH(1,(BenchmarkResults!$C$2:$C$35=CalculatedMetrics!T$1)*(BenchmarkResults!$B$2:$B$35=CalculatedMetrics!T$2)*(BenchmarkResults!$D$2:$D$35=CalculatedMetrics!T$3),0),7)} -> 614.3826 | U4: {=INDEX(BenchmarkResults!$B$2:$L$35,MATCH(1,(BenchmarkResults!$C$2:$C$35=CalculatedMetrics!T$1)*(BenchmarkResults!$B$2:$B$35=CalculatedMetrics!T$2)*(BenchmarkResults!$D$2:$D$35=CalculatedMetrics!U$3),0),7)} -> 707.707 | V4: {=INDEX(BenchmarkResults!$B$2:$L$35,MATCH(1,(BenchmarkResults!$C$2:$C$35=CalculatedMetrics!T$1)*(BenchmarkResults!$B$2:$B$35=CalculatedMetrics!T$2)*(BenchmarkResults!$D$2:$D$35=CalculatedMetrics!V$3),0),7)} -> 708.0743 | W4: {=INDEX(BenchmarkResults!$B$2:$L$35,MATCH(1,(BenchmarkResults!$C$2:$C$35=CalculatedMetrics!W$1)*(BenchmarkResults!$B$2:$B$35=CalculatedMetrics!W$2)*(BenchmarkResults!$D$2:$D$35=CalculatedMetrics!W$3),0),7)} -> 388.4461 | X4: {=INDEX(BenchmarkResults!$B$2:$L$35,MATCH(1,(BenchmarkResults!$C$2:$C$35=CalculatedMetrics!W$1)*(BenchmarkResults!$B$2:$B$35=CalculatedMetrics!W$2)*(BenchmarkResults!$D$2:$D$35=CalculatedMetrics!X$3),0),7)} -> 382.4947 | Y4: {=INDEX(BenchmarkResults!$B$2:$L$35,MATCH(1,(BenchmarkResults!$C$2:$C$35=CalculatedMetrics!W$1)*(BenchmarkResults!$B$2:$B$35=CalculatedMetrics!W$2)*(BenchmarkResults!$D$2:$D$35=CalculatedMetrics!Y$3),0),7)} -> 378.5525 | Z4: {=INDEX(BenchmarkResults!$B$2:$L$35,MATCH(1,(BenchmarkResults!$C$2:$C$35=CalculatedMetrics!Z$1)*(BenchmarkResults!$B$2:$B$35=CalculatedMetrics!Z$2)*(BenchmarkResults!$D$2:$D$35=CalculatedMetrics!Z$3),0),7)} -> 141.8517 | AA4: {=INDEX(BenchmarkResults!$B$2:$L$35,MATCH(1,(BenchmarkResults!$C$2:$C$35=CalculatedMetrics!Z$1)*(BenchmarkResults!$B$2:$B$35=CalculatedMetrics!Z$2)*(BenchmarkResults!$D$2:$D$35=CalculatedMetrics!AA$3),0),7)} -> 114.9655 | AB4: {=INDEX(BenchmarkResults!$B$2:$L$35,MATCH(1,(BenchmarkResults!$C$2:$C$35=CalculatedMetrics!Z$1)*(BenchmarkResults!$B$2:$B$35=CalculatedMetrics!Z$2)*(BenchmarkResults!$D$2:$D$35=CalculatedMetrics!AB$3),0),7)} -> 113.3426 | AC4: {=INDEX(BenchmarkResults!$B$2:$L$35,MATCH(1,(BenchmarkResults!$C$2:$C$35=CalculatedMetrics!AC$1)*(BenchmarkResults!$B$2:$B$35=CalculatedMetrics!AC$2)*(BenchmarkResults!$D$2:$D$35=CalculatedMetrics!AC$3),0),7)} -> 118.0226 | AD4: {=INDEX(BenchmarkResults!$B$2:$L$35,MATCH(1,(BenchmarkResults!$C$2:$C$35=CalculatedMetrics!AC$1)*(BenchmarkResults!$B$2:$B$35=CalculatedMetrics!AC$2)*(BenchmarkResults!$D$2:$D$35=CalculatedMetrics!AD$3),0),7)} -> 240.9751 | AE4: {=INDEX(BenchmarkResults!$B$2:$L$35,MATCH(1,(BenchmarkResults!$C$2:$C$35=CalculatedMetrics!AC$1)*(BenchmarkResults!$B$2:$B$35=CalculatedMetrics!AC$2)*(BenchmarkResults!$D$2:$D$35=CalculatedMetrics!AE$3),0),7)} -> 234.7794 | AF4: {=INDEX(BenchmarkResults!$B$2:$L$35,MATCH(1,(BenchmarkResults!$C$2:$C$35=CalculatedMetrics!AF$1)*(BenchmarkResults!$B$2:$B$35=CalculatedMetrics!AF$2)*(BenchmarkResults!$D$2:$D$35=CalculatedMetrics!AF$3),0),7)} -> 602.6768 | AG4: {=INDEX(BenchmarkResults!$B$2:$L$35,MATCH(1,(BenchmarkResults!$C$2:$C$35=CalculatedMetrics!AF$1)*(BenchmarkResults!$B$2:$B$35=CalculatedMetrics!AF$2)*(BenchmarkResults!$D$2:$D$35=CalculatedMetrics!AG$3),0),7)} -> 466.5409 | AH4: {=INDEX(BenchmarkResults!$B$2:$L$35,MATCH(1,(BenchmarkResults!$C$2:$C$35=CalculatedMetrics!AF$1)*(BenchmarkResults!$B$2:$B$35=CalculatedMetrics!AF$2)*(BenchmarkResults!$D$2:$D$35=CalculatedMetrics!AH$3),0),7)} -> 591.2841 | AI4: {=INDEX(BenchmarkResults!$B$2:$L$35,MATCH(1,(BenchmarkResults!$C$2:$C$35=CalculatedMetrics!AI$1)*(BenchmarkResults!$B$2:$B$35=CalculatedMetrics!AI$2)*(BenchmarkResults!$D$2:$D$35=CalculatedMetrics!AI$3),0),7)} -> 464.8011 | AJ4: {=INDEX(BenchmarkResults!$B$2:$L$35,MATCH(1,(BenchmarkResults!$C$2:$C$35=CalculatedMetrics!AI$1)*(BenchmarkResults!$B$2:$B$35=CalculatedMetrics!AI$2)*(BenchmarkResults!$D$2:$D$35=CalculatedMetrics!AJ$3),0),7)} -> 459.9657 | AK4: {=INDEX(BenchmarkResults!$B$2:$L$35,MATCH(1,(BenchmarkResults!$C$2:$C$35=CalculatedMetrics!AI$1)*(BenchmarkResults!$B$2:$B$35=CalculatedMetrics!AI$2)*(BenchmarkResults!$D$2:$D$35=CalculatedMetrics!AK$3),0),7)} -> 474.4045
A5: Average CPU usage % | B5: =IFERROR(AVERAGEIFS(mongodb_hardware_log!$O$3:$O$3476,mongodb_hardware_log!$A$3:$A$3476,B$2,mongodb_hardware_log!$B$3:$B$3476,B$3),"N/A") -> 20.320334 | C5: DNR | D5: DNR | E5: =IFERROR(AVERAGEIFS(mongodb_hardware_log!$O$3:$O$3476,mongodb_hardware_log!$A$3:$A$3476,E$2,mongodb_hardware_log!$B$3:$B$3476,E$3),"N/A") -> 33.246988 | F5: =IFERROR(AVERAGEIFS(mongodb_hardware_log!$O$3:$O$3476,mongodb_hardware_log!$A$3:$A$3476,E$2,mongodb_hardware_log!$B$3:$B$3476,F$3),"N/A") -> 33.248503 | G5: =IFERROR(AVERAGEIFS(mongodb_hardware_log!$O$3:$O$3476,mongodb_hardware_log!$A$3:$A$3476,E$2,mongodb_hardware_log!$B$3:$B$3476,G$3),"N/A") -> 33.274143 | H5: =IFERROR(AVERAGEIFS(mongodb_hardware_log!$O$3:$O$3476,mongodb_hardware_log!$A$3:$A$3476,H$2,mongodb_hardware_log!$B$3:$B$3476,H$3),"N/A") -> 30.5 | I5: =IFERROR(AVERAGEIFS(mongodb_hardware_log!$O$3:$O$3476,mongodb_hardware_log!$A$3:$A$3476,H$2,mongodb_hardware_log!$B$3:$B$3476,I$3),"N/A") -> 30.136364 | J5: =IFERROR(AVERAGEIFS(mongodb_hardware_log!$O$3:$O$3476,mongodb_hardware_log!$A$3:$A$3476,H$2,mongodb_hardware_log!$B$3:$B$3476,J$3),"N/A") -> 31.227273 | K5: =IFERROR(AVERAGEIFS(mongodb_hardware_log!$O$3:$O$3476,mongodb_hardware_log!$A$3:$A$3476,K$2,mongodb_hardware_log!$B$3:$B$3476,K$3),"N/A") -> 19.495902 | L5: =IFERROR(AVERAGEIFS(mongodb_hardware_log!$O$3:$O$3476,mongodb_hardware_log!$A$3:$A$3476,K$2,mongodb_hardware_log!$B$3:$B$3476,L$3),"N/A") -> 19.564 | M5: =IFERROR(AVERAGEIFS(mongodb_hardware_log!$O$3:$O$3476,mongodb_hardware_log!$A$3:$A$3476,K$2,mongodb_hardware_log!$B$3:$B$3476,M$3),"N/A") -> 19.387352 | N5: =IFERROR(AVERAGEIFS(mongodb_hardware_log!$O$3:$O$3476,mongodb_hardware_log!$A$3:$A$3476,N$2,mongodb_hardware_log!$B$3:$B$3476,N$3),"N/A") -> 29.166667 | O5: =IFERROR(AVERAGEIFS(mongodb_hardware_log!$O$3:$O$3476,mongodb_hardware_log!$A$3:$A$3476,N$2,mongodb_hardware_log!$B$3:$B$3476,O$3),"N/A") -> 31.294118 | P5: =IFERROR(AVERAGEIFS(mongodb_hardware_log!$O$3:$O$3476,mongodb_hardware_log!$A$3:$A$3476,N$2,mongodb_hardware_log!$B$3:$B$3476,P$3),"N/A") -> 29.611111 | Q5: =IFERROR(AVERAGEIFS(mongodb_hardware_log!$O$3:$O$3476,mongodb_hardware_log!$A$3:$A$3476,Q$2,mongodb_hardware_log!$B$3:$B$3476,Q$3),"N/A") -> 32.433333 | R5: =IFERROR(AVERAGEIFS(mongodb_hardware_log!$O$3:$O$3476,mongodb_hardware_log!$A$3:$A$3476,Q$2,mongodb_hardware_log!$B$3:$B$3476,R$3),"N/A") -> 35.476578 | S5: =IFERROR(AVERAGEIFS(mongodb_hardware_log!$O$3:$O$3476,mongodb_hardware_log!$A$3:$A$3476,Q$2,mongodb_hardware_log!$B$3:$B$3476,S$3),"N/A") -> 32.98998 | T5: =IFERROR(AVERAGEIFS(mysql_hardware_log!$O$3:$O$722,mysql_hardware_log!$A$3:$A$722,T$2,mysql_hardware_log!$B$3:$B$722,CalculatedMetrics!T$3),"N/A") -> 33.655738 | U5: =IFERROR(AVERAGEIFS(mysql_hardware_log!$O$3:$O$722,mysql_hardware_log!$A$3:$A$722,T$2,mysql_hardware_log!$B$3:$B$722,CalculatedMetrics!U$3),"N/A") -> 31.760563 | V5: =IFERROR(AVERAGEIFS(mysql_hardware_log!$O$3:$O$722,mysql_hardware_log!$A$3:$A$722,T$2,mysql_hardware_log!$B$3:$B$722,CalculatedMetrics!V$3),"N/A") -> 31.571429 | W5: =IFERROR(AVERAGEIFS(mysql_hardware_log!$O$3:$O$722,mysql_hardware_log!$A$3:$A$722,W$2,mysql_hardware_log!$B$3:$B$722,CalculatedMetrics!W$3),"N/A") -> 29.74359 | X5: =IFERROR(AVERAGEIFS(mysql_hardware_log!$O$3:$O$722,mysql_hardware_log!$A$3:$A$722,W$2,mysql_hardware_log!$B$3:$B$722,CalculatedMetrics!X$3),"N/A") -> 29.948718 | Y5: =IFERROR(AVERAGEIFS(mysql_hardware_log!$O$3:$O$722,mysql_hardware_log!$A$3:$A$722,W$2,mysql_hardware_log!$B$3:$B$722,CalculatedMetrics!Y$3),"N/A") -> 30.621622 | Z5: =IFERROR(AVERAGEIFS(mysql_hardware_log!$O$3:$O$722,mysql_hardware_log!$A$3:$A$722,Z$2,mysql_hardware_log!$B$3:$B$722,CalculatedMetrics!Z$3),"N/A") -> 12.866667 | AA5: =IFERROR(AVERAGEIFS(mysql_hardware_log!$O$3:$O$722,mysql_hardware_log!$A$3:$A$722,Z$2,mysql_hardware_log!$B$3:$B$722,CalculatedMetrics!AA$3),"N/A") -> 11.181818 | AB5: =IFERROR(AVERAGEIFS(mysql_hardware_log!$O$3:$O$722,mysql_hardware_log!$A$3:$A$722,Z$2,mysql_hardware_log!$B$3:$B$722,CalculatedMetrics!AB$3),"N/A") -> 11.272727 | AC5: =IFERROR(AVERAGEIFS(mysql_hardware_log!$O$3:$O$722,mysql_hardware_log!$A$3:$A$722,AC$2,mysql_hardware_log!$B$3:$B$722,CalculatedMetrics!AC$3),"N/A") -> 45.75 | AD5: =IFERROR(AVERAGEIFS(mysql_hardware_log!$O$3:$O$722,mysql_hardware_log!$A$3:$A$722,AC$2,mysql_hardware_log!$B$3:$B$722,CalculatedMetrics!AD$3),"N/A") -> 34.458333 | AE5: =IFERROR(AVERAGEIFS(mysql_hardware_log!$O$3:$O$722,mysql_hardware_log!$A$3:$A$722,AC$2,mysql_hardware_log!$B$3:$B$722,CalculatedMetrics!AE$3),"N/A") -> 33.208333 | AF5: =IFERROR(AVERAGEIFS(mysql_hardware_log!$O$3:$O$722,mysql_hardware_log!$A$3:$A$722,AF$2,mysql_hardware_log!$B$3:$B$722,CalculatedMetrics!AF$3),"N/A") -> 35.15 | AG5: =IFERROR(AVERAGEIFS(mysql_hardware_log!$O$3:$O$722,mysql_hardware_log!$A$3:$A$722,AF$2,mysql_hardware_log!$B$3:$B$722,CalculatedMetrics!AG$3),"N/A") -> 38.425532 | AH5: =IFERROR(AVERAGEIFS(mysql_hardware_log!$O$3:$O$722,mysql_hardware_log!$A$3:$A$722,AF$2,mysql_hardware_log!$B$3:$B$722,CalculatedMetrics!AH$3),"N/A") -> 35.220339 | AI5: =IFERROR(AVERAGEIFS(mysql_hardware_log!$O$3:$O$722,mysql_hardware_log!$A$3:$A$722,AI$2,mysql_hardware_log!$B$3:$B$722,CalculatedMetrics!AI$3),"N/A") -> 22.5 | AJ5: =IFERROR(AVERAGEIFS(mysql_hardware_log!$O$3:$O$722,mysql_hardware_log!$A$3:$A$722,AI$2,mysql_hardware_log!$B$3:$B$722,CalculatedMetrics!AJ$3),"N/A") -> 22.847826 | AK5: =IFERROR(AVERAGEIFS(mysql_hardware_log!$O$3:$O$722,mysql_hardware_log!$A$3:$A$722,AI$2,mysql_hardware_log!$B$3:$B$722,CalculatedMetrics!AK$3),"N/A") -> 22.854167
A6: Average CPU wait % | B6: =IFERROR(AVERAGEIFS(mongodb_hardware_log!$R$3:$R$3476,mongodb_hardware_log!$A$3:$A$3476,B$2,mongodb_hardware_log!$B$3:$B$3476,B$3),"N/A") -> 24.827298 | C6: DNR | D6: DNR | E6: =IFERROR(AVERAGEIFS(mongodb_hardware_log!$R$3:$R$3476,mongodb_hardware_log!$A$3:$A$3476,E$2,mongodb_hardware_log!$B$3:$B$3476,E$3),"N/A") -> 0.34638554 | F6: =IFERROR(AVERAGEIFS(mongodb_hardware_log!$R$3:$R$3476,mongodb_hardware_log!$A$3:$A$3476,E$2,mongodb_hardware_log!$B$3:$B$3476,F$3),"N/A") -> 0.27245509 | G6: =IFERROR(AVERAGEIFS(mongodb_hardware_log!$R$3:$R$3476,mongodb_hardware_log!$A$3:$A$3476,E$2,mongodb_hardware_log!$B$3:$B$3476,G$3),"N/A") -> 0.2305296 | H6: =IFERROR(AVERAGEIFS(mongodb_hardware_log!$R$3:$R$3476,mongodb_hardware_log!$A$3:$A$3476,H$2,mongodb_hardware_log!$B$3:$B$3476,H$3),"N/A") -> 3.4583333 | I6: =IFERROR(AVERAGEIFS(mongodb_hardware_log!$R$3:$R$3476,mongodb_hardware_log!$A$3:$A$3476,H$2,mongodb_hardware_log!$B$3:$B$3476,I$3),"N/A") -> 4.3636364 | J6: =IFERROR(AVERAGEIFS(mongodb_hardware_log!$R$3:$R$3476,mongodb_hardware_log!$A$3:$A$3476,H$2,mongodb_hardware_log!$B$3:$B$3476,J$3),"N/A") -> 3.4090909 | K6: =IFERROR(AVERAGEIFS(mongodb_hardware_log!$R$3:$R$3476,mongodb_hardware_log!$A$3:$A$3476,K$2,mongodb_hardware_log!$B$3:$B$3476,K$3),"N/A") -> 25.151639 | L6: =IFERROR(AVERAGEIFS(mongodb_hardware_log!$R$3:$R$3476,mongodb_hardware_log!$A$3:$A$3476,K$2,mongodb_hardware_log!$B$3:$B$3476,L$3),"N/A") -> 24.104 | M6: =IFERROR(AVERAGEIFS(mongodb_hardware_log!$R$3:$R$3476,mongodb_hardware_log!$A$3:$A$3476,K$2,mongodb_hardware_log!$B$3:$B$3476,M$3),"N/A") -> 24.664032 | N6: =IFERROR(AVERAGEIFS(mongodb_hardware_log!$R$3:$R$3476,mongodb_hardware_log!$A$3:$A$3476,N$2,mongodb_hardware_log!$B$3:$B$3476,N$3),"N/A") -> 7.1666667 | O6: =IFERROR(AVERAGEIFS(mongodb_hardware_log!$R$3:$R$3476,mongodb_hardware_log!$A$3:$A$3476,N$2,mongodb_hardware_log!$B$3:$B$3476,O$3),"N/A") -> 4.8823529 | P6: =IFERROR(AVERAGEIFS(mongodb_hardware_log!$R$3:$R$3476,mongodb_hardware_log!$A$3:$A$3476,N$2,mongodb_hardware_log!$B$3:$B$3476,P$3),"N/A") -> 6.5555556 | Q6: =IFERROR(AVERAGEIFS(mongodb_hardware_log!$R$3:$R$3476,mongodb_hardware_log!$A$3:$A$3476,Q$2,mongodb_hardware_log!$B$3:$B$3476,Q$3),"N/A") -> 0.70740741 | R6: =IFERROR(AVERAGEIFS(mongodb_hardware_log!$R$3:$R$3476,mongodb_hardware_log!$A$3:$A$3476,Q$2,mongodb_hardware_log!$B$3:$B$3476,R$3),"N/A") -> 0.64562118 | S6: =IFERROR(AVERAGEIFS(mongodb_hardware_log!$R$3:$R$3476,mongodb_hardware_log!$A$3:$A$3476,Q$2,mongodb_hardware_log!$B$3:$B$3476,S$3),"N/A") -> 0.69539078 | T6: =IFERROR(AVERAGEIFS(mysql_hardware_log!$R$3:$R$722,mysql_hardware_log!$A$3:$A$722,T$2,mysql_hardware_log!$B$3:$B$722,CalculatedMetrics!T$3),"N/A") -> 1.6557377 | U6: =IFERROR(AVERAGEIFS(mysql_hardware_log!$R$3:$R$722,mysql_hardware_log!$A$3:$A$722,T$2,mysql_hardware_log!$B$3:$B$722,CalculatedMetrics!U$3),"N/A") -> 1.0140845 | V6: =IFERROR(AVERAGEIFS(mysql_hardware_log!$R$3:$R$722,mysql_hardware_log!$A$3:$A$722,T$2,mysql_hardware_log!$B$3:$B$722,CalculatedMetrics!V$3),"N/A") -> 1.2 | W6: =IFERROR(AVERAGEIFS(mysql_hardware_log!$R$3:$R$722,mysql_hardware_log!$A$3:$A$722,W$2,mysql_hardware_log!$B$3:$B$722,CalculatedMetrics!W$3),"N/A") -> 4.2564103 | X6: =IFERROR(AVERAGEIFS(mysql_hardware_log!$R$3:$R$722,mysql_hardware_log!$A$3:$A$722,W$2,mysql_hardware_log!$B$3:$B$722,CalculatedMetrics!X$3),"N/A") -> 3.5641026 | Y6: =IFERROR(AVERAGEIFS(mysql_hardware_log!$R$3:$R$722,mysql_hardware_log!$A$3:$A$722,W$2,mysql_hardware_log!$B$3:$B$722,CalculatedMetrics!Y$3),"N/A") -> 2.7297297 | Z6: =IFERROR(AVERAGEIFS(mysql_hardware_log!$R$3:$R$722,mysql_hardware_log!$A$3:$A$722,Z$2,mysql_hardware_log!$B$3:$B$722,CalculatedMetrics!Z$3),"N/A") -> 4.1333333 | AA6: =IFERROR(AVERAGEIFS(mysql_hardware_log!$R$3:$R$722,mysql_hardware_log!$A$3:$A$722,Z$2,mysql_hardware_log!$B$3:$B$722,CalculatedMetrics!AA$3),"N/A") -> 4.3636364 | AB6: =IFERROR(AVERAGEIFS(mysql_hardware_log!$R$3:$R$722,mysql_hardware_log!$A$3:$A$722,Z$2,mysql_hardware_log!$B$3:$B$722,CalculatedMetrics!AB$3),"N/A") -> 4.5454545 | AC6: =IFERROR(AVERAGEIFS(mysql_hardware_log!$R$3:$R$722,mysql_hardware_log!$A$3:$A$722,AC$2,mysql_hardware_log!$B$3:$B$722,CalculatedMetrics!AC$3),"N/A") -> 0.25 | AD6: =IFERROR(AVERAGEIFS(mysql_hardware_log!$R$3:$R$722,mysql_hardware_log!$A$3:$A$722,AC$2,mysql_hardware_log!$B$3:$B$722,CalculatedMetrics!AD$3),"N/A") -> 0 | AE6: =IFERROR(AVERAGEIFS(mysql_hardware_log!$R$3:$R$722,mysql_hardware_log!$A$3:$A$722,AC$2,mysql_hardware_log!$B$3:$B$722,CalculatedMetrics!AE$3),"N/A") -> 0 | AF6: =IFERROR(AVERAGEIFS(mysql_hardware_log!$R$3:$R$722,mysql_hardware_log!$A$3:$A$722,AF$2,mysql_hardware_log!$B$3:$B$722,CalculatedMetrics!AF$3),"N/A") -> 2.9 | AG6: =IFERROR(AVERAGEIFS(mysql_hardware_log!$R$3:$R$722,mysql_hardware_log!$A$3:$A$722,AF$2,mysql_hardware_log!$B$3:$B$722,CalculatedMetrics!AG$3),"N/A") -> 2.212766 | AH6: =IFERROR(AVERAGEIFS(mysql_hardware_log!$R$3:$R$722,mysql_hardware_log!$A$3:$A$722,AF$2,mysql_hardware_log!$B$3:$B$722,CalculatedMetrics!AH$3),"N/A") -> 3.2711864 | AI6: =IFERROR(AVERAGEIFS(mysql_hardware_log!$R$3:$R$722,mysql_hardware_log!$A$3:$A$722,AI$2,mysql_hardware_log!$B$3:$B$722,CalculatedMetrics!AI$3),"N/A") -> 4.2826087 | AJ6: =IFERROR(AVERAGEIFS(mysql_hardware_log!$R$3:$R$722,mysql_hardware_log!$A$3:$A$722,AI$2,mysql_hardware_log!$B$3:$B$722,CalculatedMetrics!AJ$3),"N/A") -> 2.8043478 | AK6: =IFERROR(AVERAGEIFS(mysql_hardware_log!$R$3:$R$722,mysql_hardware_log!$A$3:$A$722,AI$2,mysql_hardware_log!$B$3:$B$722,CalculatedMetrics!AK$3),"N/A") -> 3.3333333
A7: Average CPU idle % | B7: =IFERROR(AVERAGEIFS(mongodb_hardware_log!$Q$3:$Q$3476,mongodb_hardware_log!$A$3:$A$3476,B$2,mongodb_hardware_log!$B$3:$B$3476,B$3),"N/A") -> 46.983287 | C7: DNR | D7: DNR | E7: =IFERROR(AVERAGEIFS(mongodb_hardware_log!$Q$3:$Q$3476,mongodb_hardware_log!$A$3:$A$3476,E$2,mongodb_hardware_log!$B$3:$B$3476,E$3),"N/A") -> 64.403614 | F7: =IFERROR(AVERAGEIFS(mongodb_hardware_log!$Q$3:$Q$3476,mongodb_hardware_log!$A$3:$A$3476,E$2,mongodb_hardware_log!$B$3:$B$3476,F$3),"N/A") -> 64.41018 | G7: =IFERROR(AVERAGEIFS(mongodb_hardware_log!$Q$3:$Q$3476,mongodb_hardware_log!$A$3:$A$3476,E$2,mongodb_hardware_log!$B$3:$B$3476,G$3),"N/A") -> 64.588785 | H7: =IFERROR(AVERAGEIFS(mongodb_hardware_log!$Q$3:$Q$3476,mongodb_hardware_log!$A$3:$A$3476,H$2,mongodb_hardware_log!$B$3:$B$3476,H$3),"N/A") -> 62.125 | I7: =IFERROR(AVERAGEIFS(mongodb_hardware_log!$Q$3:$Q$3476,mongodb_hardware_log!$A$3:$A$3476,H$2,mongodb_hardware_log!$B$3:$B$3476,I$3),"N/A") -> 62.136364 | J7: =IFERROR(AVERAGEIFS(mongodb_hardware_log!$Q$3:$Q$3476,mongodb_hardware_log!$A$3:$A$3476,H$2,mongodb_hardware_log!$B$3:$B$3476,J$3),"N/A") -> 62.681818 | K7: =IFERROR(AVERAGEIFS(mongodb_hardware_log!$Q$3:$Q$3476,mongodb_hardware_log!$A$3:$A$3476,K$2,mongodb_hardware_log!$B$3:$B$3476,K$3),"N/A") -> 47.237705 | L7: =IFERROR(AVERAGEIFS(mongodb_hardware_log!$Q$3:$Q$3476,mongodb_hardware_log!$A$3:$A$3476,K$2,mongodb_hardware_log!$B$3:$B$3476,L$3),"N/A") -> 47.812 | M7: =IFERROR(AVERAGEIFS(mongodb_hardware_log!$Q$3:$Q$3476,mongodb_hardware_log!$A$3:$A$3476,K$2,mongodb_hardware_log!$B$3:$B$3476,M$3),"N/A") -> 47.466403 | N7: =IFERROR(AVERAGEIFS(mongodb_hardware_log!$Q$3:$Q$3476,mongodb_hardware_log!$A$3:$A$3476,N$2,mongodb_hardware_log!$B$3:$B$3476,N$3),"N/A") -> 60 | O7: =IFERROR(AVERAGEIFS(mongodb_hardware_log!$Q$3:$Q$3476,mongodb_hardware_log!$A$3:$A$3476,N$2,mongodb_hardware_log!$B$3:$B$3476,O$3),"N/A") -> 61.235294 | P7: =IFERROR(AVERAGEIFS(mongodb_hardware_log!$Q$3:$Q$3476,mongodb_hardware_log!$A$3:$A$3476,N$2,mongodb_hardware_log!$B$3:$B$3476,P$3),"N/A") -> 60.222222 | Q7: =IFERROR(AVERAGEIFS(mongodb_hardware_log!$Q$3:$Q$3476,mongodb_hardware_log!$A$3:$A$3476,Q$2,mongodb_hardware_log!$B$3:$B$3476,Q$3),"N/A") -> 64.555556 | R7: =IFERROR(AVERAGEIFS(mongodb_hardware_log!$Q$3:$Q$3476,mongodb_hardware_log!$A$3:$A$3476,Q$2,mongodb_hardware_log!$B$3:$B$3476,R$3),"N/A") -> 61.661914 | S7: =IFERROR(AVERAGEIFS(mongodb_hardware_log!$Q$3:$Q$3476,mongodb_hardware_log!$A$3:$A$3476,Q$2,mongodb_hardware_log!$B$3:$B$3476,S$3),"N/A") -> 64.278557 | T7: =IFERROR(AVERAGEIFS(mysql_hardware_log!$Q$3:$Q$722,mysql_hardware_log!$A$3:$A$722,T$2,mysql_hardware_log!$B$3:$B$722,CalculatedMetrics!T$3),"N/A") -> 60.163934 | U7: =IFERROR(AVERAGEIFS(mysql_hardware_log!$Q$3:$Q$722,mysql_hardware_log!$A$3:$A$722,T$2,mysql_hardware_log!$B$3:$B$722,CalculatedMetrics!U$3),"N/A") -> 64.211268 | V7: =IFERROR(AVERAGEIFS(mysql_hardware_log!$Q$3:$Q$722,mysql_hardware_log!$A$3:$A$722,T$2,mysql_hardware_log!$B$3:$B$722,CalculatedMetrics!V$3),"N/A") -> 64.128571 | W7: =IFERROR(AVERAGEIFS(mysql_hardware_log!$Q$3:$Q$722,mysql_hardware_log!$A$3:$A$722,W$2,mysql_hardware_log!$B$3:$B$722,CalculatedMetrics!W$3),"N/A") -> 62.333333 | X7: =IFERROR(AVERAGEIFS(mysql_hardware_log!$Q$3:$Q$722,mysql_hardware_log!$A$3:$A$722,W$2,mysql_hardware_log!$B$3:$B$722,CalculatedMetrics!X$3),"N/A") -> 62.153846 | Y7: =IFERROR(AVERAGEIFS(mysql_hardware_log!$Q$3:$Q$722,mysql_hardware_log!$A$3:$A$722,W$2,mysql_hardware_log!$B$3:$B$722,CalculatedMetrics!Y$3),"N/A") -> 62.513514 | Z7: =IFERROR(AVERAGEIFS(mysql_hardware_log!$Q$3:$Q$722,mysql_hardware_log!$A$3:$A$722,Z$2,mysql_hardware_log!$B$3:$B$722,CalculatedMetrics!Z$3),"N/A") -> 79.933333 | AA7: =IFERROR(AVERAGEIFS(mysql_hardware_log!$Q$3:$Q$722,mysql_hardware_log!$A$3:$A$722,Z$2,mysql_hardware_log!$B$3:$B$722,CalculatedMetrics!AA$3),"N/A") -> 82.181818 | AB7: =IFERROR(AVERAGEIFS(mysql_hardware_log!$Q$3:$Q$722,mysql_hardware_log!$A$3:$A$722,Z$2,mysql_hardware_log!$B$3:$B$722,CalculatedMetrics!AB$3),"N/A") -> 82.545455 | AC7: =IFERROR(AVERAGEIFS(mysql_hardware_log!$Q$3:$Q$722,mysql_hardware_log!$A$3:$A$722,AC$2,mysql_hardware_log!$B$3:$B$722,CalculatedMetrics!AC$3),"N/A") -> 53.416667 | AD7: =IFERROR(AVERAGEIFS(mysql_hardware_log!$Q$3:$Q$722,mysql_hardware_log!$A$3:$A$722,AC$2,mysql_hardware_log!$B$3:$B$722,CalculatedMetrics!AD$3),"N/A") -> 63.416667 | AE7: =IFERROR(AVERAGEIFS(mysql_hardware_log!$Q$3:$Q$722,mysql_hardware_log!$A$3:$A$722,AC$2,mysql_hardware_log!$B$3:$B$722,CalculatedMetrics!AE$3),"N/A") -> 66 | AF7: =IFERROR(AVERAGEIFS(mysql_hardware_log!$Q$3:$Q$722,mysql_hardware_log!$A$3:$A$722,AF$2,mysql_hardware_log!$B$3:$B$722,CalculatedMetrics!AF$3),"N/A") -> 56.616667 | AG7: =IFERROR(AVERAGEIFS(mysql_hardware_log!$Q$3:$Q$722,mysql_hardware_log!$A$3:$A$722,AF$2,mysql_hardware_log!$B$3:$B$722,CalculatedMetrics!AG$3),"N/A") -> 54.893617 | AH7: =IFERROR(AVERAGEIFS(mysql_hardware_log!$Q$3:$Q$722,mysql_hardware_log!$A$3:$A$722,AF$2,mysql_hardware_log!$B$3:$B$722,CalculatedMetrics!AH$3),"N/A") -> 56.762712 | AI7: =IFERROR(AVERAGEIFS(mysql_hardware_log!$Q$3:$Q$722,mysql_hardware_log!$A$3:$A$722,AI$2,mysql_hardware_log!$B$3:$B$722,CalculatedMetrics!AI$3),"N/A") -> 61.695652 | AJ7: =IFERROR(AVERAGEIFS(mysql_hardware_log!$Q$3:$Q$722,mysql_hardware_log!$A$3:$A$722,AI$2,mysql_hardware_log!$B$3:$B$722,CalculatedMetrics!AJ$3),"N/A") -> 62.108696 | AK7: =IFERROR(AVERAGEIFS(mysql_hardware_log!$Q$3:$Q$722,mysql_hardware_log!$A$3:$A$722,AI$2,mysql_hardware_log!$B$3:$B$722,CalculatedMetrics!AK$3),"N/A") -> 61.75
A8: Min free memory (KB) | B8: =_xlfn.MINIFS(mongodb_hardware_log!$F$3:$F$3476,mongodb_hardware_log!$A$3:$A$3476,CalculatedMetrics!B$2,mongodb_hardware_log!$B$3:$B$3476,CalculatedMetrics!B$3) -> 99408 | C8: DNR | D8: DNR | E8: =_xlfn.MINIFS(mongodb_hardware_log!$F$3:$F$3476,mongodb_hardware_log!$A$3:$A$3476,CalculatedMetrics!E$2,mongodb_hardware_log!$B$3:$B$3476,CalculatedMetrics!E$3) -> 107560 | F8: =_xlfn.MINIFS(mongodb_hardware_log!$F$3:$F$3476,mongodb_hardware_log!$A$3:$A$3476,CalculatedMetrics!E$2,mongodb_hardware_log!$B$3:$B$3476,CalculatedMetrics!F$3) -> 115584 | G8: =_xlfn.MINIFS(mongodb_hardware_log!$F$3:$F$3476,mongodb_hardware_log!$A$3:$A$3476,CalculatedMetrics!E$2,mongodb_hardware_log!$B$3:$B$3476,CalculatedMetrics!G$3) -> 99960 | H8: =_xlfn.MINIFS(mongodb_hardware_log!$F$3:$F$3476,mongodb_hardware_log!$A$3:$A$3476,CalculatedMetrics!H$2,mongodb_hardware_log!$B$3:$B$3476,CalculatedMetrics!H$3) -> 104264 | I8: =_xlfn.MINIFS(mongodb_hardware_log!$F$3:$F$3476,mongodb_hardware_log!$A$3:$A$3476,CalculatedMetrics!H$2,mongodb_hardware_log!$B$3:$B$3476,CalculatedMetrics!I$3) -> 103080 | J8: =_xlfn.MINIFS(mongodb_hardware_log!$F$3:$F$3476,mongodb_hardware_log!$A$3:$A$3476,CalculatedMetrics!H$2,mongodb_hardware_log!$B$3:$B$3476,CalculatedMetrics!J$3) -> 104404 | K8: =_xlfn.MINIFS(mongodb_hardware_log!$F$3:$F$3476,mongodb_hardware_log!$A$3:$A$3476,CalculatedMetrics!K$2,mongodb_hardware_log!$B$3:$B$3476,CalculatedMetrics!K$3) -> 98364 | L8: =_xlfn.MINIFS(mongodb_hardware_log!$F$3:$F$3476,mongodb_hardware_log!$A$3:$A$3476,CalculatedMetrics!K$2,mongodb_hardware_log!$B$3:$B$3476,CalculatedMetrics!L$3) -> 100816 | M8: =_xlfn.MINIFS(mongodb_hardware_log!$F$3:$F$3476,mongodb_hardware_log!$A$3:$A$3476,CalculatedMetrics!K$2,mongodb_hardware_log!$B$3:$B$3476,CalculatedMetrics!M$3) -> 104648 | N8: =_xlfn.MINIFS(mongodb_hardware_log!$F$3:$F$3476,mongodb_hardware_log!$A$3:$A$3476,CalculatedMetrics!N$2,mongodb_hardware_log!$B$3:$B$3476,CalculatedMetrics!N$3) -> 111216 | O8: =_xlfn.MINIFS(mongodb_hardware_log!$F$3:$F$3476,mongodb_hardware_log!$A$3:$A$3476,CalculatedMetrics!N$2,mongodb_hardware_log!$B$3:$B$3476,CalculatedMetrics!O$3) -> 105144 | P8: =_xlfn.MINIFS(mongodb_hardware_log!$F$3:$F$3476,mongodb_hardware_log!$A$3:$A$3476,CalculatedMetrics!N$2,mongodb_hardware_log!$B$3:$B$3476,CalculatedMetrics!P$3) -> 112408 | Q8: =_xlfn.MINIFS(mongodb_hardware_log!$F$3:$F$3476,mongodb_hardware_log!$A$3:$A$3476,CalculatedMetrics!Q$2,mongodb_hardware_log!$B$3:$B$3476,CalculatedMetrics!Q$3) -> 105228 | R8: =_xlfn.MINIFS(mongodb_hardware_log!$F$3:$F$3476,mongodb_hardware_log!$A$3:$A$3476,CalculatedMetrics!Q$2,mongodb_hardware_log!$B$3:$B$3476,CalculatedMetrics!R$3) -> 104624 | S8: =_xlfn.MINIFS(mongodb_hardware_log!$F$3:$F$3476,mongodb_hardware_log!$A$3:$A$3476,CalculatedMetrics!Q$2,mongodb_hardware_log!$B$3:$B$3476,CalculatedMetrics!S$3) -> 104372 | T8: =_xlfn.MINIFS(mysql_hardware_log!$F$3:$F$722,mysql_hardware_log!$A$3:$A$722,CalculatedMetrics!T$2,mysql_hardware_log!$B$3:$B$722,CalculatedMetrics!T$3) -> 97484 | U8: =_xlfn.MINIFS(mysql_hardware_log!$F$3:$F$722,mysql_hardware_log!$A$3:$A$722,CalculatedMetrics!T$2,mysql_hardware_log!$B$3:$B$722,CalculatedMetrics!U$3) -> 103820 | V8: =_xlfn.MINIFS(mysql_hardware_log!$F$3:$F$722,mysql_hardware_log!$A$3:$A$722,CalculatedMetrics!T$2,mysql_hardware_log!$B$3:$B$722,CalculatedMetrics!V$3) -> 103724 | W8: =_xlfn.MINIFS(mysql_hardware_log!$F$3:$F$722,mysql_hardware_log!$A$3:$A$722,CalculatedMetrics!W$2,mysql_hardware_log!$B$3:$B$722,CalculatedMetrics!W$3) -> 104232 | X8: =_xlfn.MINIFS(mysql_hardware_log!$F$3:$F$722,mysql_hardware_log!$A$3:$A$722,CalculatedMetrics!W$2,mysql_hardware_log!$B$3:$B$722,CalculatedMetrics!X$3) -> 105140 | Y8: =_xlfn.MINIFS(mysql_hardware_log!$F$3:$F$722,mysql_hardware_log!$A$3:$A$722,CalculatedMetrics!W$2,mysql_hardware_log!$B$3:$B$722,CalculatedMetrics!Y$3) -> 104340 | Z8: =_xlfn.MINIFS(mysql_hardware_log!$F$3:$F$722,mysql_hardware_log!$A$3:$A$722,CalculatedMetrics!Z$2,mysql_hardware_log!$B$3:$B$722,CalculatedMetrics!Z$3) -> 119316 | AA8: =_xlfn.MINIFS(mysql_hardware_log!$F$3:$F$722,mysql_hardware_log!$A$3:$A$722,CalculatedMetrics!Z$2,mysql_hardware_log!$B$3:$B$722,CalculatedMetrics!AA$3) -> 511604 | AB8: =_xlfn.MINIFS(mysql_hardware_log!$F$3:$F$722,mysql_hardware_log!$A$3:$A$722,CalculatedMetrics!Z$2,mysql_hardware_log!$B$3:$B$722,CalculatedMetrics!AB$3) -> 106568 | AC8: =_xlfn.MINIFS(mysql_hardware_log!$F$3:$F$722,mysql_hardware_log!$A$3:$A$722,CalculatedMetrics!AC$2,mysql_hardware_log!$B$3:$B$722,CalculatedMetrics!AC$3) -> 686976 | AD8: =_xlfn.MINIFS(mysql_hardware_log!$F$3:$F$722,mysql_hardware_log!$A$3:$A$722,CalculatedMetrics!AC$2,mysql_hardware_log!$B$3:$B$722,CalculatedMetrics!AD$3) -> 180680 | AE8: =_xlfn.MINIFS(mysql_hardware_log!$F$3:$F$722,mysql_hardware_log!$A$3:$A$722,CalculatedMetrics!AC$2,mysql_hardware_log!$B$3:$B$722,CalculatedMetrics!AE$3) -> 1176084 | AF8: =_xlfn.MINIFS(mysql_hardware_log!$F$3:$F$722,mysql_hardware_log!$A$3:$A$722,CalculatedMetrics!AF$2,mysql_hardware_log!$B$3:$B$722,CalculatedMetrics!AF$3) -> 104024 | AG8: =_xlfn.MINIFS(mysql_hardware_log!$F$3:$F$722,mysql_hardware_log!$A$3:$A$722,CalculatedMetrics!AF$2,mysql_hardware_log!$B$3:$B$722,CalculatedMetrics!AG$3) -> 108816 | AH8: =_xlfn.MINIFS(mysql_hardware_log!$F$3:$F$722,mysql_hardware_log!$A$3:$A$722,CalculatedMetrics!AF$2,mysql_hardware_log!$B$3:$B$722,CalculatedMetrics!AH$3) -> 99332 | AI8: =_xlfn.MINIFS(mysql_hardware_log!$F$3:$F$722,mysql_hardware_log!$A$3:$A$722,CalculatedMetrics!AI$2,mysql_hardware_log!$B$3:$B$722,CalculatedMetrics!AI$3) -> 145324 | AJ8: =_xlfn.MINIFS(mysql_hardware_log!$F$3:$F$722,mysql_hardware_log!$A$3:$A$722,CalculatedMetrics!AI$2,mysql_hardware_log!$B$3:$B$722,CalculatedMetrics!AJ$3) -> 112332 | AK8: =_xlfn.MINIFS(mysql_hardware_log!$F$3:$F$722,mysql_hardware_log!$A$3:$A$722,CalculatedMetrics!AI$2,mysql_hardware_log!$B$3:$B$722,CalculatedMetrics!AK$3) -> 107372
A9: Cache at query start (KB) | B9: {=INDEX(mongodb_hardware_log!$A$3:$T$3476,MATCH(1,(mongodb_hardware_log!$A$3:$A$3476=B$2)*(mongodb_hardware_log!$B$3:$B$3476=B$3),0),8)} -> 2351504 | C9: DNR | D9: DNR | E9: {=INDEX(mongodb_hardware_log!$A$3:$T$3476,MATCH(1,(mongodb_hardware_log!$A$3:$A$3476=E$2)*(mongodb_hardware_log!$B$3:$B$3476=E$3),0),8)} -> 2264696 | F9: {=INDEX(mongodb_hardware_log!$A$3:$T$3476,MATCH(1,(mongodb_hardware_log!$A$3:$A$3476=E$2)*(mongodb_hardware_log!$B$3:$B$3476=F$3),0),8)} -> 2140988 | G9: {=INDEX(mongodb_hardware_log!$A$3:$T$3476,MATCH(1,(mongodb_hardware_log!$A$3:$A$3476=E$2)*(mongodb_hardware_log!$B$3:$B$3476=G$3),0),8)} -> 1873744 | H9: {=INDEX(mongodb_hardware_log!$A$3:$T$3476,MATCH(1,(mongodb_hardware_log!$A$3:$A$3476=H$2)*(mongodb_hardware_log!$B$3:$B$3476=H$3),0),8)} -> 2154068 | I9: {=INDEX(mongodb_hardware_log!$A$3:$T$3476,MATCH(1,(mongodb_hardware_log!$A$3:$A$3476=H$2)*(mongodb_hardware_log!$B$3:$B$3476=I$3),0),8)} -> 1590412 | J9: {=INDEX(mongodb_hardware_log!$A$3:$T$3476,MATCH(1,(mongodb_hardware_log!$A$3:$A$3476=H$2)*(mongodb_hardware_log!$B$3:$B$3476=J$3),0),8)} -> 1950464 | K9: {=INDEX(mongodb_hardware_log!$A$3:$T$3476,MATCH(1,(mongodb_hardware_log!$A$3:$A$3476=K$2)*(mongodb_hardware_log!$B$3:$B$3476=K$3),0),8)} -> 2134212 | L9: {=INDEX(mongodb_hardware_log!$A$3:$T$3476,MATCH(1,(mongodb_hardware_log!$A$3:$A$3476=K$2)*(mongodb_hardware_log!$B$3:$B$3476=L$3),0),8)} -> 2338228 | M9: {=INDEX(mongodb_hardware_log!$A$3:$T$3476,MATCH(1,(mongodb_hardware_log!$A$3:$A$3476=K$2)*(mongodb_hardware_log!$B$3:$B$3476=M$3),0),8)} -> 2259240 | N9: {=INDEX(mongodb_hardware_log!$A$3:$T$3476,MATCH(1,(mongodb_hardware_log!$A$3:$A$3476=N$2)*(mongodb_hardware_log!$B$3:$B$3476=N$3),0),8)} -> 1930412 | O9: {=INDEX(mongodb_hardware_log!$A$3:$T$3476,MATCH(1,(mongodb_hardware_log!$A$3:$A$3476=N$2)*(mongodb_hardware_log!$B$3:$B$3476=O$3),0),8)} -> 2188308 | P9: {=INDEX(mongodb_hardware_log!$A$3:$T$3476,MATCH(1,(mongodb_hardware_log!$A$3:$A$3476=N$2)*(mongodb_hardware_log!$B$3:$B$3476=P$3),0),8)} -> 2181816 | Q9: {=INDEX(mongodb_hardware_log!$A$3:$T$3476,MATCH(1,(mongodb_hardware_log!$A$3:$A$3476=Q$2)*(mongodb_hardware_log!$B$3:$B$3476=Q$3),0),8)} -> 2287240 | R9: {=INDEX(mongodb_hardware_log!$A$3:$T$3476,MATCH(1,(mongodb_hardware_log!$A$3:$A$3476=Q$2)*(mongodb_hardware_log!$B$3:$B$3476=R$3),0),8)} -> 1592908 | S9: {=INDEX(mongodb_hardware_log!$A$3:$T$3476,MATCH(1,(mongodb_hardware_log!$A$3:$A$3476=Q$2)*(mongodb_hardware_log!$B$3:$B$3476=S$3),0),8)} -> 1585916 | T9: {=INDEX(mysql_hardware_log!$A$3:$T$722,MATCH(1,(mysql_hardware_log!$A$3:$A$722=T$2)*(mysql_hardware_log!$B$3:$B$722=T$3),0),8)} -> 1160288 | U9: {=INDEX(mysql_hardware_log!$A$3:$T$722,MATCH(1,(mysql_hardware_log!$A$3:$A$722=T$2)*(mysql_hardware_log!$B$3:$B$722=U$3),0),8)} -> 3587072 | V9: {=INDEX(mysql_hardware_log!$A$3:$T$722,MATCH(1,(mysql_hardware_log!$A$3:$A$722=T$2)*(mysql_hardware_log!$B$3:$B$722=V$3),0),8)} -> 3390028 | W9: {=INDEX(mysql_hardware_log!$A$3:$T$722,MATCH(1,(mysql_hardware_log!$A$3:$A$722=W$2)*(mysql_hardware_log!$B$3:$B$722=W$3),0),8)} -> 3616748 | X9: {=INDEX(mysql_hardware_log!$A$3:$T$722,MATCH(1,(mysql_hardware_log!$A$3:$A$722=W$2)*(mysql_hardware_log!$B$3:$B$722=X$3),0),8)} -> 3590352 | Y9: {=INDEX(mysql_hardware_log!$A$3:$T$722,MATCH(1,(mysql_hardware_log!$A$3:$A$722=W$2)*(mysql_hardware_log!$B$3:$B$722=Y$3),0),8)} -> 3610968 | Z9: {=INDEX(mysql_hardware_log!$A$3:$T$722,MATCH(1,(mysql_hardware_log!$A$3:$A$722=Z$2)*(mysql_hardware_log!$B$3:$B$722=Z$3),0),8)} -> 2973836 | AA9: {=INDEX(mysql_hardware_log!$A$3:$T$722,MATCH(1,(mysql_hardware_log!$A$3:$A$722=Z$2)*(mysql_hardware_log!$B$3:$B$722=AA$3),0),8)} -> 2980708 | AB9: {=INDEX(mysql_hardware_log!$A$3:$T$722,MATCH(1,(mysql_hardware_log!$A$3:$A$722=Z$2)*(mysql_hardware_log!$B$3:$B$722=AB$3),0),8)} -> 2846604 | AC9: {=INDEX(mysql_hardware_log!$A$3:$T$722,MATCH(1,(mysql_hardware_log!$A$3:$A$722=AC$2)*(mysql_hardware_log!$B$3:$B$722=AC$3),0),8)} -> 2785056 | AD9: {=INDEX(mysql_hardware_log!$A$3:$T$722,MATCH(1,(mysql_hardware_log!$A$3:$A$722=AC$2)*(mysql_hardware_log!$B$3:$B$722=AD$3),0),8)} -> 3027668 | AE9: {=INDEX(mysql_hardware_log!$A$3:$T$722,MATCH(1,(mysql_hardware_log!$A$3:$A$722=AC$2)*(mysql_hardware_log!$B$3:$B$722=AE$3),0),8)} -> 2440916 | AF9: {=INDEX(mysql_hardware_log!$A$3:$T$722,MATCH(1,(mysql_hardware_log!$A$3:$A$722=AF$2)*(mysql_hardware_log!$B$3:$B$722=AF$3),0),8)} -> 2477680 | AG9: {=INDEX(mysql_hardware_log!$A$3:$T$722,MATCH(1,(mysql_hardware_log!$A$3:$A$722=AF$2)*(mysql_hardware_log!$B$3:$B$722=AG$3),0),8)} -> 3411656 | AH9: {=INDEX(mysql_hardware_log!$A$3:$T$722,MATCH(1,(mysql_hardware_log!$A$3:$A$722=AF$2)*(mysql_hardware_log!$B$3:$B$722=AH$3),0),8)} -> 3227304 | AI9: {=INDEX(mysql_hardware_log!$A$3:$T$722,MATCH(1,(mysql_hardware_log!$A$3:$A$722=AI$2)*(mysql_hardware_log!$B$3:$B$722=AI$3),0),8)} -> 3338532 | AJ9: {=INDEX(mysql_hardware_log!$A$3:$T$722,MATCH(1,(mysql_hardware_log!$A$3:$A$722=AI$2)*(mysql_hardware_log!$B$3:$B$722=AJ$3),0),8)} -> 2609136 | AK9: {=INDEX(mysql_hardware_log!$A$3:$T$722,MATCH(1,(mysql_hardware_log!$A$3:$A$722=AI$2)*(mysql_hardware_log!$B$3:$B$722=AK$3),0),8)} -> 2012832
